2025-02-19 01:03:55,262 [ERROR] KartenWarp: Error loading localization; falling back to Japanese
Traceback (most recent call last):
  File "C:\Github\TR_mod\.tools\KartenWarp\dev\kartenwarp\localization.py", line 66, in load_localization
    with open(file_path, "r", encoding="utf-8") as f:
         ^^^^^^^^^^^^^^^^^^^^^^^^^^^^^^^^^^^^^^
  File "C:\Program Files\WindowsApps\PythonSoftwareFoundation.Python.3.11_3.11.2544.0_x64__qbz5n2kfra8p0\Lib\unittest\mock.py", line 1124, in __call__
    return self._mock_call(*args, **kwargs)
           ^^^^^^^^^^^^^^^^^^^^^^^^^^^^^^^^
  File "C:\Program Files\WindowsApps\PythonSoftwareFoundation.Python.3.11_3.11.2544.0_x64__qbz5n2kfra8p0\Lib\unittest\mock.py", line 1128, in _mock_call
    return self._execute_mock_call(*args, **kwargs)
           ^^^^^^^^^^^^^^^^^^^^^^^^^^^^^^^^^^^^^^^^
  File "C:\Program Files\WindowsApps\PythonSoftwareFoundation.Python.3.11_3.11.2544.0_x64__qbz5n2kfra8p0\Lib\unittest\mock.py", line 1183, in _execute_mock_call
    raise effect
ValueError: JSON Decode Error
2025-02-19 01:03:55,264 [ERROR] KartenWarp: Error loading fallback localization. Using minimal built-in fallback.
Traceback (most recent call last):
  File "C:\Github\TR_mod\.tools\KartenWarp\dev\kartenwarp\localization.py", line 78, in load_localization
    with open(fallback_path, "r", encoding="utf-8") as f:
         ^^^^^^^^^^^^^^^^^^^^^^^^^^^^^^^^^^^^^^^^^^
  File "C:\Program Files\WindowsApps\PythonSoftwareFoundation.Python.3.11_3.11.2544.0_x64__qbz5n2kfra8p0\Lib\unittest\mock.py", line 1124, in __call__
    return self._mock_call(*args, **kwargs)
           ^^^^^^^^^^^^^^^^^^^^^^^^^^^^^^^^
  File "C:\Program Files\WindowsApps\PythonSoftwareFoundation.Python.3.11_3.11.2544.0_x64__qbz5n2kfra8p0\Lib\unittest\mock.py", line 1128, in _mock_call
    return self._execute_mock_call(*args, **kwargs)
           ^^^^^^^^^^^^^^^^^^^^^^^^^^^^^^^^^^^^^^^^
  File "C:\Program Files\WindowsApps\PythonSoftwareFoundation.Python.3.11_3.11.2544.0_x64__qbz5n2kfra8p0\Lib\unittest\mock.py", line 1183, in _execute_mock_call
    raise effect
  File "C:\Github\TR_mod\.tools\KartenWarp\dev\kartenwarp\localization.py", line 66, in load_localization
    with open(file_path, "r", encoding="utf-8") as f:
         ^^^^^^^^^^^^^^^^^^^^^^^^^^^^^^^^^^^^^^
  File "C:\Program Files\WindowsApps\PythonSoftwareFoundation.Python.3.11_3.11.2544.0_x64__qbz5n2kfra8p0\Lib\unittest\mock.py", line 1124, in __call__
    return self._mock_call(*args, **kwargs)
           ^^^^^^^^^^^^^^^^^^^^^^^^^^^^^^^^
  File "C:\Program Files\WindowsApps\PythonSoftwareFoundation.Python.3.11_3.11.2544.0_x64__qbz5n2kfra8p0\Lib\unittest\mock.py", line 1128, in _mock_call
    return self._execute_mock_call(*args, **kwargs)
           ^^^^^^^^^^^^^^^^^^^^^^^^^^^^^^^^^^^^^^^^
  File "C:\Program Files\WindowsApps\PythonSoftwareFoundation.Python.3.11_3.11.2544.0_x64__qbz5n2kfra8p0\Lib\unittest\mock.py", line 1183, in _execute_mock_call
    raise effect
ValueError: JSON Decode Error
2025-02-19 01:03:55,326 [ERROR] KartenWarp: Error loading localization; falling back to Japanese
Traceback (most recent call last):
  File "C:\Github\TR_mod\.tools\KartenWarp\dev\kartenwarp\localization.py", line 66, in load_localization
    with open(file_path, "r", encoding="utf-8") as f:
         ^^^^^^^^^^^^^^^^^^^^^^^^^^^^^^^^^^^^^^
  File "C:\Program Files\WindowsApps\PythonSoftwareFoundation.Python.3.11_3.11.2544.0_x64__qbz5n2kfra8p0\Lib\unittest\mock.py", line 1124, in __call__
    return self._mock_call(*args, **kwargs)
           ^^^^^^^^^^^^^^^^^^^^^^^^^^^^^^^^
  File "C:\Program Files\WindowsApps\PythonSoftwareFoundation.Python.3.11_3.11.2544.0_x64__qbz5n2kfra8p0\Lib\unittest\mock.py", line 1128, in _mock_call
    return self._execute_mock_call(*args, **kwargs)
           ^^^^^^^^^^^^^^^^^^^^^^^^^^^^^^^^^^^^^^^^
  File "C:\Program Files\WindowsApps\PythonSoftwareFoundation.Python.3.11_3.11.2544.0_x64__qbz5n2kfra8p0\Lib\unittest\mock.py", line 1183, in _execute_mock_call
    raise effect
FileNotFoundError
2025-02-19 01:03:55,326 [ERROR] KartenWarp: Error loading fallback localization. Using minimal built-in fallback.
Traceback (most recent call last):
  File "C:\Github\TR_mod\.tools\KartenWarp\dev\kartenwarp\localization.py", line 66, in load_localization
    with open(file_path, "r", encoding="utf-8") as f:
         ^^^^^^^^^^^^^^^^^^^^^^^^^^^^^^^^^^^^^^
  File "C:\Program Files\WindowsApps\PythonSoftwareFoundation.Python.3.11_3.11.2544.0_x64__qbz5n2kfra8p0\Lib\unittest\mock.py", line 1124, in __call__
    return self._mock_call(*args, **kwargs)
           ^^^^^^^^^^^^^^^^^^^^^^^^^^^^^^^^
  File "C:\Program Files\WindowsApps\PythonSoftwareFoundation.Python.3.11_3.11.2544.0_x64__qbz5n2kfra8p0\Lib\unittest\mock.py", line 1128, in _mock_call
    return self._execute_mock_call(*args, **kwargs)
           ^^^^^^^^^^^^^^^^^^^^^^^^^^^^^^^^^^^^^^^^
  File "C:\Program Files\WindowsApps\PythonSoftwareFoundation.Python.3.11_3.11.2544.0_x64__qbz5n2kfra8p0\Lib\unittest\mock.py", line 1183, in _execute_mock_call
    raise effect
FileNotFoundError

During handling of the above exception, another exception occurred:

Traceback (most recent call last):
  File "C:\Github\TR_mod\.tools\KartenWarp\dev\kartenwarp\localization.py", line 78, in load_localization
    with open(fallback_path, "r", encoding="utf-8") as f:
         ^^^^^^^^^^^^^^^^^^^^^^^^^^^^^^^^^^^^^^^^^^
  File "C:\Program Files\WindowsApps\PythonSoftwareFoundation.Python.3.11_3.11.2544.0_x64__qbz5n2kfra8p0\Lib\unittest\mock.py", line 1124, in __call__
    return self._mock_call(*args, **kwargs)
           ^^^^^^^^^^^^^^^^^^^^^^^^^^^^^^^^
  File "C:\Program Files\WindowsApps\PythonSoftwareFoundation.Python.3.11_3.11.2544.0_x64__qbz5n2kfra8p0\Lib\unittest\mock.py", line 1128, in _mock_call
    return self._execute_mock_call(*args, **kwargs)
           ^^^^^^^^^^^^^^^^^^^^^^^^^^^^^^^^^^^^^^^^
  File "C:\Program Files\WindowsApps\PythonSoftwareFoundation.Python.3.11_3.11.2544.0_x64__qbz5n2kfra8p0\Lib\unittest\mock.py", line 1183, in _execute_mock_call
    raise effect
FileNotFoundError
2025-02-19 01:03:55,615 [ERROR] KartenWarp: TPS regularization parameter invalid
Traceback (most recent call last):
  File "C:\Github\TR_mod\.tools\KartenWarp\dev\kartenwarp\ui\options_dialog.py", line 111, in accept
    raise ValueError("Regularization parameter must be positive.")
ValueError: Regularization parameter must be positive.
2025-02-19 01:03:57,277 [ERROR] KartenWarp.Transform: Game image not loaded
2025-02-19 01:03:57,280 [ERROR] KartenWarp.Transform: Insufficient correspondence points
